{"recv_mono_ns":1550051607256666,"recv_wall_ns":1783307645740734000,"source":"Kalshi","channel":"orderbook_delta","source_ticker":"KXMLBTOTAL-26JUL052130BOSLAA-14","source_sequence":5,"sid":1,"stream_epoch":1,"raw":"{\"type\":\"orderbook_delta\",\"sid\":1,\"seq\":5,\"msg\":{\"market_ticker\":\"KXMLBTOTAL-26JUL052130BOSLAA-14\",\"market_id\":\"3bc0a9cb-36d7-48db-8f37-f76ba3733be9\",\"price_dollars\":\"0.2000\",\"delta_fp\":\"-10.00\",\"side\":\"yes\",\"ts\":\"2026-07-06T03:14:05.791454Z\",\"ts_ms\":1783307645791}}\n"}
{"recv_mono_ns":1550144044870291,"recv_wall_ns":1783307738178072000,"source":"Kalshi","channel":"orderbook_delta","source_ticker":"KXMLBTOTAL-26JUL052130BOSLAA-14","source_sequence":2070,"sid":1,"stream_epoch":1,"raw":"{\"type\":\"orderbook_delta\",\"sid\":1,\"seq\":2070,\"msg\":{\"market_ticker\":\"KXMLBTOTAL-26JUL052130BOSLAA-14\",\"market_id\":\"3bc0a9cb-36d7-48db-8f37-f76ba3733be9\",\"price_dollars\":\"0.7700\",\"delta_fp\":\"4.00\",\"side\":\"no\",\"ts\":\"2026-07-06T03:15:38.223297Z\",\"ts_ms\":1783307738223}}\n"}
{"recv_mono_ns":1550212237486625,"recv_wall_ns":1783307806370485000,"source":"Kalshi","channel":"orderbook_delta","source_ticker":"KXMLBTOTAL-26JUL052130BOSLAA-14","source_sequence":4134,"sid":1,"stream_epoch":1,"raw":"{\"type\":\"orderbook_delta\",\"sid\":1,\"seq\":4134,\"msg\":{\"market_ticker\":\"KXMLBTOTAL-26JUL052130BOSLAA-14\",\"market_id\":\"3bc0a9cb-36d7-48db-8f37-f76ba3733be9\",\"price_dollars\":\"0.1300\",\"delta_fp\":\"100.00\",\"side\":\"yes\",\"ts\":\"2026-07-06T03:16:46.421785Z\",\"ts_ms\":1783307806421}}\n"}
{"recv_mono_ns":1550246708486833,"recv_wall_ns":1783307840841383000,"source":"Kalshi","channel":"orderbook_delta","source_ticker":"KXMLBTOTAL-26JUL052130BOSLAA-14","source_sequence":6198,"sid":1,"stream_epoch":1,"raw":"{\"type\":\"orderbook_delta\",\"sid\":1,\"seq\":6198,\"msg\":{\"market_ticker\":\"KXMLBTOTAL-26JUL052130BOSLAA-14\",\"market_id\":\"3bc0a9cb-36d7-48db-8f37-f76ba3733be9\",\"price_dollars\":\"0.2800\",\"delta_fp\":\"-30.00\",\"side\":\"no\",\"ts\":\"2026-07-06T03:17:20.896294Z\",\"ts_ms\":1783307840896}}\n"}
{"recv_mono_ns":1550288879821166,"recv_wall_ns":1783307883012591000,"source":"Kalshi","channel":"orderbook_delta","source_ticker":"KXMLBSPREAD-26JUL052130BOSLAA-BOS5","source_sequence":8262,"sid":1,"stream_epoch":1,"raw":"{\"type\":\"orderbook_delta\",\"sid\":1,\"seq\":8262,\"msg\":{\"market_ticker\":\"KXMLBSPREAD-26JUL052130BOSLAA-BOS5\",\"market_id\":\"fbcbe60b-3659-4eab-9b3d-b3fc1ec63eff\",\"price_dollars\":\"0.7400\",\"delta_fp\":\"-21.00\",\"side\":\"no\",\"ts\":\"2026-07-06T03:18:03.062688Z\",\"ts_ms\":1783307883062}}\n"}
{"recv_mono_ns":1550311860924166,"recv_wall_ns":1783307905993626000,"source":"Kalshi","channel":"orderbook_delta","source_ticker":"KXMLBTOTAL-26JUL052130BOSLAA-14","source_sequence":10326,"sid":1,"stream_epoch":1,"raw":"{\"type\":\"orderbook_delta\",\"sid\":1,\"seq\":10326,\"msg\":{\"market_ticker\":\"KXMLBTOTAL-26JUL052130BOSLAA-14\",\"market_id\":\"3bc0a9cb-36d7-48db-8f37-f76ba3733be9\",\"price_dollars\":\"0.1900\",\"delta_fp\":\"-20.00\",\"side\":\"yes\",\"ts\":\"2026-07-06T03:18:26.040637Z\",\"ts_ms\":1783307906040}}\n"}
{"recv_mono_ns":1550340762472500,"recv_wall_ns":1783307934895088000,"source":"Kalshi","channel":"orderbook_delta","source_ticker":"KXMLBSPREAD-26JUL052130BOSLAA-BOS5","source_sequence":12390,"sid":1,"stream_epoch":1,"raw":"{\"type\":\"orderbook_delta\",\"sid\":1,\"seq\":12390,\"msg\":{\"market_ticker\":\"KXMLBSPREAD-26JUL052130BOSLAA-BOS5\",\"market_id\":\"fbcbe60b-3659-4eab-9b3d-b3fc1ec63eff\",\"price_dollars\":\"0.7300\",\"delta_fp\":\"73.44\",\"side\":\"no\",\"ts\":\"2026-07-06T03:18:54.948334Z\",\"ts_ms\":1783307934948}}\n"}
{"recv_mono_ns":1550370850861500,"recv_wall_ns":1783307964866955000,"source":"Kalshi","channel":"orderbook_delta","source_ticker":"KXMLBSPREAD-26JUL052130BOSLAA-BOS5","source_sequence":14454,"sid":1,"stream_epoch":1,"raw":"{\"type\":\"orderbook_delta\",\"sid\":1,\"seq\":14454,\"msg\":{\"market_ticker\":\"KXMLBSPREAD-26JUL052130BOSLAA-BOS5\",\"market_id\":\"fbcbe60b-3659-4eab-9b3d-b3fc1ec63eff\",\"price_dollars\":\"0.7400\",\"delta_fp\":\"1.00\",\"side\":\"no\",\"ts\":\"2026-07-06T03:19:25.033293Z\",\"ts_ms\":1783307965033}}\n"}
{"recv_mono_ns":1550405527720333,"recv_wall_ns":1783307999542766000,"source":"Kalshi","channel":"orderbook_delta","source_ticker":"KXMLBTOTAL-26JUL052130BOSLAA-14","source_sequence":16518,"sid":1,"stream_epoch":1,"raw":"{\"type\":\"orderbook_delta\",\"sid\":1,\"seq\":16518,\"msg\":{\"market_ticker\":\"KXMLBTOTAL-26JUL052130BOSLAA-14\",\"market_id\":\"3bc0a9cb-36d7-48db-8f37-f76ba3733be9\",\"price_dollars\":\"0.7300\",\"delta_fp\":\"79.09\",\"side\":\"no\",\"ts\":\"2026-07-06T03:19:59.713161Z\",\"ts_ms\":1783307999713}}\n"}
{"recv_mono_ns":1550431700408000,"recv_wall_ns":1783308025714666000,"source":"Kalshi","channel":"orderbook_delta","source_ticker":"KXMLBSPREAD-26JUL052130BOSLAA-BOS5","source_sequence":18582,"sid":1,"stream_epoch":1,"raw":"{\"type\":\"orderbook_delta\",\"sid\":1,\"seq\":18582,\"msg\":{\"market_ticker\":\"KXMLBSPREAD-26JUL052130BOSLAA-BOS5\",\"market_id\":\"fbcbe60b-3659-4eab-9b3d-b3fc1ec63eff\",\"price_dollars\":\"0.6500\",\"delta_fp\":\"1.00\",\"side\":\"no\",\"ts\":\"2026-07-06T03:20:25.884213Z\",\"ts_ms\":1783308025884}}\n"}
{"recv_mono_ns":1550471335381916,"recv_wall_ns":1783308065348449000,"source":"Kalshi","channel":"orderbook_delta","source_ticker":"KXMLBTOTAL-26JUL052130BOSLAA-14","source_sequence":20646,"sid":1,"stream_epoch":1,"raw":"{\"type\":\"orderbook_delta\",\"sid\":1,\"seq\":20646,\"msg\":{\"market_ticker\":\"KXMLBTOTAL-26JUL052130BOSLAA-14\",\"market_id\":\"3bc0a9cb-36d7-48db-8f37-f76ba3733be9\",\"price_dollars\":\"0.1900\",\"delta_fp\":\"83.00\",\"side\":\"no\",\"ts\":\"2026-07-06T03:21:05.52251Z\",\"ts_ms\":1783308065522}}\n"}
{"recv_mono_ns":1550492482160833,"recv_wall_ns":1783308086494592000,"source":"Kalshi","channel":"orderbook_delta","source_ticker":"KXMLBTOTAL-26JUL052130BOSLAA-14","source_sequence":22710,"sid":1,"stream_epoch":1,"raw":"{\"type\":\"orderbook_delta\",\"sid\":1,\"seq\":22710,\"msg\":{\"market_ticker\":\"KXMLBTOTAL-26JUL052130BOSLAA-14\",\"market_id\":\"3bc0a9cb-36d7-48db-8f37-f76ba3733be9\",\"price_dollars\":\"0.1800\",\"delta_fp\":\"-1.00\",\"side\":\"yes\",\"ts\":\"2026-07-06T03:21:26.665953Z\",\"ts_ms\":1783308086665}}\n"}
{"recv_mono_ns":1550504152080666,"recv_wall_ns":1783308098164161000,"source":"Kalshi","channel":"orderbook_delta","source_ticker":"KXMLBTOTAL-26JUL052130BOSLAA-14","source_sequence":24774,"sid":1,"stream_epoch":1,"raw":"{\"type\":\"orderbook_delta\",\"sid\":1,\"seq\":24774,\"msg\":{\"market_ticker\":\"KXMLBTOTAL-26JUL052130BOSLAA-14\",\"market_id\":\"3bc0a9cb-36d7-48db-8f37-f76ba3733be9\",\"price_dollars\":\"0.7000\",\"delta_fp\":\"-40.00\",\"side\":\"no\",\"ts\":\"2026-07-06T03:21:38.339516Z\",\"ts_ms\":1783308098339}}\n"}
{"recv_mono_ns":1550524803417916,"recv_wall_ns":1783308118814877000,"source":"Kalshi","channel":"orderbook_delta","source_ticker":"KXMLBTOTAL-26JUL052130BOSLAA-14","source_sequence":26838,"sid":1,"stream_epoch":1,"raw":"{\"type\":\"orderbook_delta\",\"sid\":1,\"seq\":26838,\"msg\":{\"market_ticker\":\"KXMLBTOTAL-26JUL052130BOSLAA-14\",\"market_id\":\"3bc0a9cb-36d7-48db-8f37-f76ba3733be9\",\"price_dollars\":\"0.5800\",\"delta_fp\":\"-65.93\",\"side\":\"no\",\"ts\":\"2026-07-06T03:21:58.991602Z\",\"ts_ms\":1783308118991}}\n"}
{"recv_mono_ns":1550554521299500,"recv_wall_ns":1783308148531865000,"source":"Kalshi","channel":"orderbook_delta","source_ticker":"KXMLBTOTAL-26JUL052130BOSLAA-14","source_sequence":28902,"sid":1,"stream_epoch":1,"raw":"{\"type\":\"orderbook_delta\",\"sid\":1,\"seq\":28902,\"msg\":{\"market_ticker\":\"KXMLBTOTAL-26JUL052130BOSLAA-14\",\"market_id\":\"3bc0a9cb-36d7-48db-8f37-f76ba3733be9\",\"price_dollars\":\"0.7800\",\"delta_fp\":\"-40.00\",\"side\":\"no\",\"ts\":\"2026-07-06T03:22:28.706597Z\",\"ts_ms\":1783308148706}}\n"}
{"recv_mono_ns":1550576231818500,"recv_wall_ns":1783308170241731000,"source":"Kalshi","channel":"orderbook_delta","source_ticker":"KXMLBTOTAL-26JUL052130BOSLAA-14","source_sequence":30966,"sid":1,"stream_epoch":1,"raw":"{\"type\":\"orderbook_delta\",\"sid\":1,\"seq\":30966,\"msg\":{\"market_ticker\":\"KXMLBTOTAL-26JUL052130BOSLAA-14\",\"market_id\":\"3bc0a9cb-36d7-48db-8f37-f76ba3733be9\",\"price_dollars\":\"0.1500\",\"delta_fp\":\"30.00\",\"side\":\"yes\",\"ts\":\"2026-07-06T03:22:50.414268Z\",\"ts_ms\":1783308170414}}\n"}
{"recv_mono_ns":1550611240941000,"recv_wall_ns":1783308205249801000,"source":"Kalshi","channel":"orderbook_delta","source_ticker":"KXMLBTOTAL-26JUL052130BOSLAA-16","source_sequence":33030,"sid":1,"stream_epoch":1,"raw":"{\"type\":\"orderbook_delta\",\"sid\":1,\"seq\":33030,\"msg\":{\"market_ticker\":\"KXMLBTOTAL-26JUL052130BOSLAA-16\",\"market_id\":\"5ffdd88c-e74f-4e53-b1d7-ef0a88789734\",\"price_dollars\":\"0.2800\",\"delta_fp\":\"-44.90\",\"side\":\"no\",\"ts\":\"2026-07-06T03:23:25.427536Z\",\"ts_ms\":1783308205427}}\n"}
{"recv_mono_ns":1550673483688416,"recv_wall_ns":1783308267490677000,"source":"Kalshi","channel":"orderbook_delta","source_ticker":"KXMLBTOTAL-26JUL052130BOSLAA-16","source_sequence":35094,"sid":1,"stream_epoch":1,"raw":"{\"type\":\"orderbook_delta\",\"sid\":1,\"seq\":35094,\"msg\":{\"market_ticker\":\"KXMLBTOTAL-26JUL052130BOSLAA-16\",\"market_id\":\"5ffdd88c-e74f-4e53-b1d7-ef0a88789734\",\"price_dollars\":\"0.8400\",\"delta_fp\":\"24.00\",\"side\":\"no\",\"ts\":\"2026-07-06T03:24:27.671877Z\",\"ts_ms\":1783308267671}}\n"}
{"recv_mono_ns":1550806003556416,"recv_wall_ns":1783308400006529000,"source":"Kalshi","channel":"orderbook_delta","source_ticker":"KXMLBTOTAL-26JUL052130BOSLAA-14","source_sequence":37158,"sid":1,"stream_epoch":1,"raw":"{\"type\":\"orderbook_delta\",\"sid\":1,\"seq\":37158,\"msg\":{\"market_ticker\":\"KXMLBTOTAL-26JUL052130BOSLAA-14\",\"market_id\":\"3bc0a9cb-36d7-48db-8f37-f76ba3733be9\",\"price_dollars\":\"0.0500\",\"delta_fp\":\"-50.00\",\"side\":\"yes\",\"ts\":\"2026-07-06T03:26:40.193497Z\",\"ts_ms\":1783308400193}}\n"}
{"recv_mono_ns":1550829249876208,"recv_wall_ns":1783308423252144000,"source":"Kalshi","channel":"orderbook_delta","source_ticker":"KXMLBTOTAL-26JUL052130BOSLAA-16","source_sequence":39222,"sid":1,"stream_epoch":1,"raw":"{\"type\":\"orderbook_delta\",\"sid\":1,\"seq\":39222,\"msg\":{\"market_ticker\":\"KXMLBTOTAL-26JUL052130BOSLAA-16\",\"market_id\":\"5ffdd88c-e74f-4e53-b1d7-ef0a88789734\",\"price_dollars\":\"0.5100\",\"delta_fp\":\"-43.00\",\"side\":\"no\",\"ts\":\"2026-07-06T03:27:03.437584Z\",\"ts_ms\":1783308423437}}\n"}
{"recv_mono_ns":1550861181044541,"recv_wall_ns":1783308455182351000,"source":"Kalshi","channel":"orderbook_delta","source_ticker":"KXMLBTOTAL-26JUL052130BOSLAA-14","source_sequence":41286,"sid":1,"stream_epoch":1,"raw":"{\"type\":\"orderbook_delta\",\"sid\":1,\"seq\":41286,\"msg\":{\"market_ticker\":\"KXMLBTOTAL-26JUL052130BOSLAA-14\",\"market_id\":\"3bc0a9cb-36d7-48db-8f37-f76ba3733be9\",\"price_dollars\":\"0.7700\",\"delta_fp\":\"-1.00\",\"side\":\"no\",\"ts\":\"2026-07-06T03:27:35.372005Z\",\"ts_ms\":1783308455372}}\n"}
{"recv_mono_ns":1550905819090375,"recv_wall_ns":1783308499819055000,"source":"Kalshi","channel":"orderbook_delta","source_ticker":"KXMLBTOTAL-26JUL052130BOSLAA-14","source_sequence":43350,"sid":1,"stream_epoch":1,"raw":"{\"type\":\"orderbook_delta\",\"sid\":1,\"seq\":43350,\"msg\":{\"market_ticker\":\"KXMLBTOTAL-26JUL052130BOSLAA-14\",\"market_id\":\"3bc0a9cb-36d7-48db-8f37-f76ba3733be9\",\"price_dollars\":\"0.5900\",\"delta_fp\":\"58.72\",\"side\":\"no\",\"ts\":\"2026-07-06T03:28:20.00156Z\",\"ts_ms\":1783308500001}}\n"}
{"recv_mono_ns":1550924766740833,"recv_wall_ns":1783308518766136000,"source":"Kalshi","channel":"orderbook_delta","source_ticker":"KXMLBTOTAL-26JUL052130BOSLAA-14","source_sequence":45414,"sid":1,"stream_epoch":1,"raw":"{\"type\":\"orderbook_delta\",\"sid\":1,\"seq\":45414,\"msg\":{\"market_ticker\":\"KXMLBTOTAL-26JUL052130BOSLAA-14\",\"market_id\":\"3bc0a9cb-36d7-48db-8f37-f76ba3733be9\",\"price_dollars\":\"0.3200\",\"delta_fp\":\"39.28\",\"side\":\"no\",\"ts\":\"2026-07-06T03:28:38.956091Z\",\"ts_ms\":1783308518956}}\n"}
{"recv_mono_ns":1550943280187958,"recv_wall_ns":1783308537279026000,"source":"Kalshi","channel":"orderbook_delta","source_ticker":"KXMLBTOTAL-26JUL052130BOSLAA-14","source_sequence":47478,"sid":1,"stream_epoch":1,"raw":"{\"type\":\"orderbook_delta\",\"sid\":1,\"seq\":47478,\"msg\":{\"market_ticker\":\"KXMLBTOTAL-26JUL052130BOSLAA-14\",\"market_id\":\"3bc0a9cb-36d7-48db-8f37-f76ba3733be9\",\"price_dollars\":\"0.3500\",\"delta_fp\":\"58.72\",\"side\":\"no\",\"ts\":\"2026-07-06T03:28:57.46609Z\",\"ts_ms\":1783308537466}}\n"}
{"recv_mono_ns":1550954643573708,"recv_wall_ns":1783308548642070000,"source":"Kalshi","channel":"orderbook_delta","source_ticker":"KXMLBTOTAL-26JUL052130BOSLAA-14","source_sequence":49542,"sid":1,"stream_epoch":1,"raw":"{\"type\":\"orderbook_delta\",\"sid\":1,\"seq\":49542,\"msg\":{\"market_ticker\":\"KXMLBTOTAL-26JUL052130BOSLAA-14\",\"market_id\":\"3bc0a9cb-36d7-48db-8f37-f76ba3733be9\",\"price_dollars\":\"0.8400\",\"delta_fp\":\"40.00\",\"side\":\"no\",\"ts\":\"2026-07-06T03:29:08.834447Z\",\"ts_ms\":1783308548834}}\n"}
{"recv_mono_ns":1551104641617666,"recv_wall_ns":1783308698635604000,"source":"Kalshi","channel":"orderbook_delta","source_ticker":"KXMLBTOTAL-26JUL052130BOSLAA-14","source_sequence":51606,"sid":1,"stream_epoch":1,"raw":"{\"type\":\"orderbook_delta\",\"sid\":1,\"seq\":51606,\"msg\":{\"market_ticker\":\"KXMLBTOTAL-26JUL052130BOSLAA-14\",\"market_id\":\"3bc0a9cb-36d7-48db-8f37-f76ba3733be9\",\"price_dollars\":\"0.4100\",\"delta_fp\":\"387.00\",\"side\":\"no\",\"ts\":\"2026-07-06T03:31:38.829184Z\",\"ts_ms\":1783308698829}}\n"}
{"recv_mono_ns":1551126635035666,"recv_wall_ns":1783308720628361000,"source":"Kalshi","channel":"orderbook_delta","source_ticker":"KXMLBTOTAL-26JUL052130BOSLAA-16","source_sequence":53670,"sid":1,"stream_epoch":1,"raw":"{\"type\":\"orderbook_delta\",\"sid\":1,\"seq\":53670,\"msg\":{\"market_ticker\":\"KXMLBTOTAL-26JUL052130BOSLAA-16\",\"market_id\":\"5ffdd88c-e74f-4e53-b1d7-ef0a88789734\",\"price_dollars\":\"0.5300\",\"delta_fp\":\"-22.77\",\"side\":\"no\",\"ts\":\"2026-07-06T03:32:00.82619Z\",\"ts_ms\":1783308720826}}\n"}
{"recv_mono_ns":1551142525219208,"recv_wall_ns":1783308736518067000,"source":"Kalshi","channel":"orderbook_delta","source_ticker":"KXMLBTOTAL-26JUL052130BOSLAA-14","source_sequence":55734,"sid":1,"stream_epoch":1,"raw":"{\"type\":\"orderbook_delta\",\"sid\":1,\"seq\":55734,\"msg\":{\"market_ticker\":\"KXMLBTOTAL-26JUL052130BOSLAA-14\",\"market_id\":\"3bc0a9cb-36d7-48db-8f37-f76ba3733be9\",\"price_dollars\":\"0.3300\",\"delta_fp\":\"-56.57\",\"side\":\"no\",\"ts\":\"2026-07-06T03:32:16.71807Z\",\"ts_ms\":1783308736718}}\n"}
{"recv_mono_ns":1551164798748333,"recv_wall_ns":1783308758790926000,"source":"Kalshi","channel":"orderbook_delta","source_ticker":"KXMLBSPREAD-26JUL052130BOSLAA-BOS5","source_sequence":57798,"sid":1,"stream_epoch":1,"raw":"{\"type\":\"orderbook_delta\",\"sid\":1,\"seq\":57798,\"msg\":{\"market_ticker\":\"KXMLBSPREAD-26JUL052130BOSLAA-BOS5\",\"market_id\":\"fbcbe60b-3659-4eab-9b3d-b3fc1ec63eff\",\"price_dollars\":\"0.8000\",\"delta_fp\":\"800.00\",\"side\":\"no\",\"ts\":\"2026-07-06T03:32:38.98951Z\",\"ts_ms\":1783308758989}}\n"}
{"recv_mono_ns":1551195315921791,"recv_wall_ns":1783308789307182000,"source":"Kalshi","channel":"orderbook_delta","source_ticker":"KXMLBTOTAL-26JUL052130BOSLAA-14","source_sequence":59862,"sid":1,"stream_epoch":1,"raw":"{\"type\":\"orderbook_delta\",\"sid\":1,\"seq\":59862,\"msg\":{\"market_ticker\":\"KXMLBTOTAL-26JUL052130BOSLAA-14\",\"market_id\":\"3bc0a9cb-36d7-48db-8f37-f76ba3733be9\",\"price_dollars\":\"0.2600\",\"delta_fp\":\"65.00\",\"side\":\"no\",\"ts\":\"2026-07-06T03:33:09.506756Z\",\"ts_ms\":1783308789506}}\n"}
{"recv_mono_ns":1551262404814833,"recv_wall_ns":1783308856394058000,"source":"Kalshi","channel":"orderbook_delta","source_ticker":"KXMLBSPREAD-26JUL052130BOSLAA-BOS5","source_sequence":61926,"sid":1,"stream_epoch":1,"raw":"{\"type\":\"orderbook_delta\",\"sid\":1,\"seq\":61926,\"msg\":{\"market_ticker\":\"KXMLBSPREAD-26JUL052130BOSLAA-BOS5\",\"market_id\":\"fbcbe60b-3659-4eab-9b3d-b3fc1ec63eff\",\"price_dollars\":\"0.1800\",\"delta_fp\":\"4.00\",\"side\":\"yes\",\"ts\":\"2026-07-06T03:34:16.594334Z\",\"ts_ms\":1783308856594}}\n"}
{"recv_mono_ns":1551281011154083,"recv_wall_ns":1783308874999838000,"source":"Kalshi","channel":"orderbook_delta","source_ticker":"KXMLBSPREAD-26JUL052130BOSLAA-BOS5","source_sequence":63990,"sid":1,"stream_epoch":1,"raw":"{\"type\":\"orderbook_delta\",\"sid\":1,\"seq\":63990,\"msg\":{\"market_ticker\":\"KXMLBSPREAD-26JUL052130BOSLAA-BOS5\",\"market_id\":\"fbcbe60b-3659-4eab-9b3d-b3fc1ec63eff\",\"price_dollars\":\"0.7100\",\"delta_fp\":\"-21.00\",\"side\":\"no\",\"ts\":\"2026-07-06T03:34:35.204134Z\",\"ts_ms\":1783308875204}}\n"}
{"recv_mono_ns":1551314424989291,"recv_wall_ns":1783308908412668000,"source":"Kalshi","channel":"orderbook_delta","source_ticker":"KXMLBTOTAL-26JUL052130BOSLAA-14","source_sequence":66054,"sid":1,"stream_epoch":1,"raw":"{\"type\":\"orderbook_delta\",\"sid\":1,\"seq\":66054,\"msg\":{\"market_ticker\":\"KXMLBTOTAL-26JUL052130BOSLAA-14\",\"market_id\":\"3bc0a9cb-36d7-48db-8f37-f76ba3733be9\",\"price_dollars\":\"0.2000\",\"delta_fp\":\"-36.41\",\"side\":\"no\",\"ts\":\"2026-07-06T03:35:08.618875Z\",\"ts_ms\":1783308908618}}\n"}
{"recv_mono_ns":1551346053490000,"recv_wall_ns":1783308940040218000,"source":"Kalshi","channel":"orderbook_delta","source_ticker":"KXMLBTOTAL-26JUL052130BOSLAA-16","source_sequence":68118,"sid":1,"stream_epoch":1,"raw":"{\"type\":\"orderbook_delta\",\"sid\":1,\"seq\":68118,\"msg\":{\"market_ticker\":\"KXMLBTOTAL-26JUL052130BOSLAA-16\",\"market_id\":\"5ffdd88c-e74f-4e53-b1d7-ef0a88789734\",\"price_dollars\":\"0.0500\",\"delta_fp\":\"-200.00\",\"side\":\"yes\",\"ts\":\"2026-07-06T03:35:40.242099Z\",\"ts_ms\":1783308940242}}\n"}
{"recv_mono_ns":1551362173035291,"recv_wall_ns":1783308956159279000,"source":"Kalshi","channel":"orderbook_delta","source_ticker":"KXMLBTOTAL-26JUL052130BOSLAA-14","source_sequence":70182,"sid":1,"stream_epoch":1,"raw":"{\"type\":\"orderbook_delta\",\"sid\":1,\"seq\":70182,\"msg\":{\"market_ticker\":\"KXMLBTOTAL-26JUL052130BOSLAA-14\",\"market_id\":\"3bc0a9cb-36d7-48db-8f37-f76ba3733be9\",\"price_dollars\":\"0.7300\",\"delta_fp\":\"24.00\",\"side\":\"no\",\"ts\":\"2026-07-06T03:35:56.364805Z\",\"ts_ms\":1783308956364}}\n"}
{"recv_mono_ns":1551417273453875,"recv_wall_ns":1783309011258041000,"source":"Kalshi","channel":"orderbook_delta","source_ticker":"KXMLBTOTAL-26JUL052130BOSLAA-14","source_sequence":72246,"sid":1,"stream_epoch":1,"raw":"{\"type\":\"orderbook_delta\",\"sid\":1,\"seq\":72246,\"msg\":{\"market_ticker\":\"KXMLBTOTAL-26JUL052130BOSLAA-14\",\"market_id\":\"3bc0a9cb-36d7-48db-8f37-f76ba3733be9\",\"price_dollars\":\"0.1700\",\"delta_fp\":\"-42.77\",\"side\":\"yes\",\"ts\":\"2026-07-06T03:36:51.460404Z\",\"ts_ms\":1783309011460}}\n"}
{"recv_mono_ns":1551445321994416,"recv_wall_ns":1783309039305738000,"source":"Kalshi","channel":"orderbook_delta","source_ticker":"KXMLBSPREAD-26JUL052130BOSLAA-BOS5","source_sequence":74310,"sid":1,"stream_epoch":1,"raw":"{\"type\":\"orderbook_delta\",\"sid\":1,\"seq\":74310,\"msg\":{\"market_ticker\":\"KXMLBSPREAD-26JUL052130BOSLAA-BOS5\",\"market_id\":\"fbcbe60b-3659-4eab-9b3d-b3fc1ec63eff\",\"price_dollars\":\"0.2700\",\"delta_fp\":\"1.00\",\"side\":\"yes\",\"ts\":\"2026-07-06T03:37:19.508345Z\",\"ts_ms\":1783309039508}}\n"}
{"recv_mono_ns":1551480830145333,"recv_wall_ns":1783309074812821000,"source":"Kalshi","channel":"orderbook_delta","source_ticker":"KXMLBSPREAD-26JUL052130BOSLAA-BOS5","source_sequence":76374,"sid":1,"stream_epoch":1,"raw":"{\"type\":\"orderbook_delta\",\"sid\":1,\"seq\":76374,\"msg\":{\"market_ticker\":\"KXMLBSPREAD-26JUL052130BOSLAA-BOS5\",\"market_id\":\"fbcbe60b-3659-4eab-9b3d-b3fc1ec63eff\",\"price_dollars\":\"0.2700\",\"delta_fp\":\"1.00\",\"side\":\"yes\",\"ts\":\"2026-07-06T03:37:42.621561Z\",\"ts_ms\":1783309062621}}\n"}
{"recv_mono_ns":1551501040692000,"recv_wall_ns":1783309095022760000,"source":"Kalshi","channel":"orderbook_delta","source_ticker":"KXMLBTOTAL-26JUL052130BOSLAA-14","source_sequence":78438,"sid":1,"stream_epoch":1,"raw":"{\"type\":\"orderbook_delta\",\"sid\":1,\"seq\":78438,\"msg\":{\"market_ticker\":\"KXMLBTOTAL-26JUL052130BOSLAA-14\",\"market_id\":\"3bc0a9cb-36d7-48db-8f37-f76ba3733be9\",\"price_dollars\":\"0.3400\",\"delta_fp\":\"537.00\",\"side\":\"no\",\"ts\":\"2026-07-06T03:38:15.233607Z\",\"ts_ms\":1783309095233}}\n"}
{"recv_mono_ns":1551513405271375,"recv_wall_ns":1783309107386968000,"source":"Kalshi","channel":"orderbook_delta","source_ticker":"KXMLBTOTAL-26JUL052130BOSLAA-14","source_sequence":80502,"sid":1,"stream_epoch":1,"raw":"{\"type\":\"orderbook_delta\",\"sid\":1,\"seq\":80502,\"msg\":{\"market_ticker\":\"KXMLBTOTAL-26JUL052130BOSLAA-14\",\"market_id\":\"3bc0a9cb-36d7-48db-8f37-f76ba3733be9\",\"price_dollars\":\"0.1800\",\"delta_fp\":\"-30.00\",\"side\":\"yes\",\"ts\":\"2026-07-06T03:38:27.597347Z\",\"ts_ms\":1783309107597}}\n"}
{"recv_mono_ns":1551540865808916,"recv_wall_ns":1783309134846680000,"source":"Kalshi","channel":"orderbook_delta","source_ticker":"KXMLBTOTAL-26JUL052130BOSLAA-14","source_sequence":82566,"sid":1,"stream_epoch":1,"raw":"{\"type\":\"orderbook_delta\",\"sid\":1,\"seq\":82566,\"msg\":{\"market_ticker\":\"KXMLBTOTAL-26JUL052130BOSLAA-14\",\"market_id\":\"3bc0a9cb-36d7-48db-8f37-f76ba3733be9\",\"price_dollars\":\"0.7300\",\"delta_fp\":\"24.00\",\"side\":\"no\",\"ts\":\"2026-07-06T03:38:55.056652Z\",\"ts_ms\":1783309135056}}\n"}
{"recv_mono_ns":1551574156376666,"recv_wall_ns":1783309168136247000,"source":"Kalshi","channel":"orderbook_delta","source_ticker":"KXMLBSPREAD-26JUL052130BOSLAA-BOS5","source_sequence":84630,"sid":1,"stream_epoch":1,"raw":"{\"type\":\"orderbook_delta\",\"sid\":1,\"seq\":84630,\"msg\":{\"market_ticker\":\"KXMLBSPREAD-26JUL052130BOSLAA-BOS5\",\"market_id\":\"fbcbe60b-3659-4eab-9b3d-b3fc1ec63eff\",\"price_dollars\":\"0.5600\",\"delta_fp\":\"-3.00\",\"side\":\"no\",\"ts\":\"2026-07-06T03:39:28.349622Z\",\"ts_ms\":1783309168349}}\n"}
{"recv_mono_ns":1551591710261000,"recv_wall_ns":1783309185689603000,"source":"Kalshi","channel":"orderbook_delta","source_ticker":"KXMLBTOTAL-26JUL052130BOSLAA-14","source_sequence":86694,"sid":1,"stream_epoch":1,"raw":"{\"type\":\"orderbook_delta\",\"sid\":1,\"seq\":86694,\"msg\":{\"market_ticker\":\"KXMLBTOTAL-26JUL052130BOSLAA-14\",\"market_id\":\"3bc0a9cb-36d7-48db-8f37-f76ba3733be9\",\"price_dollars\":\"0.2600\",\"delta_fp\":\"567.00\",\"side\":\"no\",\"ts\":\"2026-07-06T03:39:45.90471Z\",\"ts_ms\":1783309185904}}\n"}
{"recv_mono_ns":1551603958683166,"recv_wall_ns":1783309197937657000,"source":"Kalshi","channel":"orderbook_delta","source_ticker":"KXMLBTOTAL-26JUL052130BOSLAA-14","source_sequence":88758,"sid":1,"stream_epoch":1,"raw":"{\"type\":\"orderbook_delta\",\"sid\":1,\"seq\":88758,\"msg\":{\"market_ticker\":\"KXMLBTOTAL-26JUL052130BOSLAA-14\",\"market_id\":\"3bc0a9cb-36d7-48db-8f37-f76ba3733be9\",\"price_dollars\":\"0.7100\",\"delta_fp\":\"-597.00\",\"side\":\"no\",\"ts\":\"2026-07-06T03:39:58.152102Z\",\"ts_ms\":1783309198152}}\n"}
{"recv_mono_ns":1551646300216541,"recv_wall_ns":1783309240277918000,"source":"Kalshi","channel":"orderbook_delta","source_ticker":"KXMLBTOTAL-26JUL052130BOSLAA-14","source_sequence":90822,"sid":1,"stream_epoch":1,"raw":"{\"type\":\"orderbook_delta\",\"sid\":1,\"seq\":90822,\"msg\":{\"market_ticker\":\"KXMLBTOTAL-26JUL052130BOSLAA-14\",\"market_id\":\"3bc0a9cb-36d7-48db-8f37-f76ba3733be9\",\"price_dollars\":\"0.4400\",\"delta_fp\":\"81.11\",\"side\":\"no\",\"ts\":\"2026-07-06T03:40:40.494275Z\",\"ts_ms\":1783309240494}}\n"}
{"recv_mono_ns":1551672375900083,"recv_wall_ns":1783309266352817000,"source":"Kalshi","channel":"orderbook_delta","source_ticker":"KXMLBTOTAL-26JUL052130BOSLAA-14","source_sequence":92886,"sid":1,"stream_epoch":1,"raw":"{\"type\":\"orderbook_delta\",\"sid\":1,\"seq\":92886,\"msg\":{\"market_ticker\":\"KXMLBTOTAL-26JUL052130BOSLAA-14\",\"market_id\":\"3bc0a9cb-36d7-48db-8f37-f76ba3733be9\",\"price_dollars\":\"0.4200\",\"delta_fp\":\"76.18\",\"side\":\"no\",\"ts\":\"2026-07-06T03:41:06.570773Z\",\"ts_ms\":1783309266570}}\n"}
{"recv_mono_ns":1551754882816791,"recv_wall_ns":1783309348857264000,"source":"Kalshi","channel":"orderbook_delta","source_ticker":"KXMLBTOTAL-26JUL052130BOSLAA-14","source_sequence":94950,"sid":1,"stream_epoch":1,"raw":"{\"type\":\"orderbook_delta\",\"sid\":1,\"seq\":94950,\"msg\":{\"market_ticker\":\"KXMLBTOTAL-26JUL052130BOSLAA-14\",\"market_id\":\"3bc0a9cb-36d7-48db-8f37-f76ba3733be9\",\"price_dollars\":\"0.2700\",\"delta_fp\":\"333.34\",\"side\":\"no\",\"ts\":\"2026-07-06T03:42:29.07213Z\",\"ts_ms\":1783309349072}}\n"}
{"recv_mono_ns":1551778366759208,"recv_wall_ns":1783309372340503000,"source":"Kalshi","channel":"orderbook_delta","source_ticker":"KXMLBTOTAL-26JUL052130BOSLAA-14","source_sequence":97014,"sid":1,"stream_epoch":1,"raw":"{\"type\":\"orderbook_delta\",\"sid\":1,\"seq\":97014,\"msg\":{\"market_ticker\":\"KXMLBTOTAL-26JUL052130BOSLAA-14\",\"market_id\":\"3bc0a9cb-36d7-48db-8f37-f76ba3733be9\",\"price_dollars\":\"0.6800\",\"delta_fp\":\"40.00\",\"side\":\"no\",\"ts\":\"2026-07-06T03:42:52.562787Z\",\"ts_ms\":1783309372562}}\n"}
{"recv_mono_ns":1551808827605416,"recv_wall_ns":1783309402800435000,"source":"Kalshi","channel":"orderbook_delta","source_ticker":"KXMLBTOTAL-26JUL052130BOSLAA-16","source_sequence":99078,"sid":1,"stream_epoch":1,"raw":"{\"type\":\"orderbook_delta\",\"sid\":1,\"seq\":99078,\"msg\":{\"market_ticker\":\"KXMLBTOTAL-26JUL052130BOSLAA-16\",\"market_id\":\"5ffdd88c-e74f-4e53-b1d7-ef0a88789734\",\"price_dollars\":\"0.2500\",\"delta_fp\":\"-50.28\",\"side\":\"no\",\"ts\":\"2026-07-06T03:43:23.02275Z\",\"ts_ms\":1783309403022}}\n"}
{"recv_mono_ns":1551818972508833,"recv_wall_ns":1783309412945033000,"source":"Kalshi","channel":"orderbook_delta","source_ticker":"KXMLBTOTAL-26JUL052130BOSLAA-14","source_sequence":101142,"sid":1,"stream_epoch":1,"raw":"{\"type\":\"orderbook_delta\",\"sid\":1,\"seq\":101142,\"msg\":{\"market_ticker\":\"KXMLBTOTAL-26JUL052130BOSLAA-14\",\"market_id\":\"3bc0a9cb-36d7-48db-8f37-f76ba3733be9\",\"price_dollars\":\"0.4300\",\"delta_fp\":\"74.41\",\"side\":\"no\",\"ts\":\"2026-07-06T03:43:33.169833Z\",\"ts_ms\":1783309413169}}\n"}
